# 14. 예외처리

## 14.1 예외처리
프로그램에서 에러가 발생했을 때, 에러를 핸들링하는 기능으로 try...except 문을 사용할 수 있다. 즉, try 블럭 내의 어느 문장에서 에러가 발생하면, except 문으로 이동하고 예외 처리를 할 수 있다. try 문은 또한 finally 문을 가질 수도 있는데, finally 블럭은 try 블럭이 정상적으로 실행되든, 에러가 발생하여 except 블럭이 실행되든 상관없이 항상 마지막에 실행된다.

```python
try:
  문장1
  문장2
except:
  예외처리
finally:
  마지막에 항상 수행
```

위의 except 문은 except 뒤에 아무것도 쓰지 않았는데, 이는 어떤 에러이든 발생하면 해당 except 블럭을 수행하라는 의미이다. except 뒤에 "에러타입"을 적거나 "에러타입 as 에러변수"를 적을 수가 있는데, 이는 특정한 타입의 에러가 발생했을 때만 해당 except 블럭을 실행하라는 뜻이다. 에러변수까지 지정했으면, 해당 에러변수를 excep 블럭 안에서 사용할 수 있다. 아래 예제를 보면, except가 2개 있는데, 첫번째는 IndexError가 발생했을 때만 그 블럭을 실행하며, 두번째는 일반적인 모든 Exception 이 발생했을 때 해당 블럭을 실행하라는 의미이다. 즉, 먼저 IndexError 인지 검사하고, 아니면 다음 except를 계속 순차적으로 체크하게 된다. except가 여러 개인 경우는 범위가 좁은 특별한 에러타입을 앞에 쓰고 보다 일반적인 에러타입을 뒤에 쓰게 된다.

```python
def calc(values):
    sum = None
    # try...except...else
    try:
       sum = values[0] + values[1] + values[2]
    except IndexError as err:
        print('인덱스에러')
    except Exception as err:
        print(str(err))
    else:
        print('에러없음')
    finally:
        print(sum)
 
# 테스트
calc([1, 2, 3, 6]) # 출력: 에러없음 6
calc([1, 2])       # 출력: 인덱스에러 None
```

또한, 위의 예제에서 else문 있는데, 이는 에러가 발생하지 않을 때 실행하게 되는 블럭이다. 그리고 finally 블럭은 항상 마지막에 실행되는 코드 블럭이다.

만약 복수 Exception들이 동일한 except 블럭을 갖는다면, 아래와 같이 이들 Expception들을 하나의 except 문에 묶어서 쓸 수도 있다.

```python
def calc(values):
    sum = None
    try:
       sum = values[0] + values[1] + values[2]
    except (IndexError, ValueError):
        print('오류발생')
 
    print(sum)
```

## 14.2 에러무시와 에러생성
발생된 Exception을 그냥 무시하기 위해서는 보통 pass 문을 사용하며, 또한 개발자가 에러를 던지기 위해서는 raise문을 사용한다.

raise 뒤에 아무것도 없는 경우는 현재 Exception을 그대로 던지게 된다. 또한 raise 뒤에 특정한 에러타입과 에러메시지 (Optional)를 넣어 개발자가 정의한 에러를 발생시킬 수 있다. 예를 들어 아래 예제는 raise 뒤에 Exception 에러타입과 에러메시지를 넣어 특별한 에러메시지를 전달하고 있다.

```python
# pass 를 사용한 예
try:
   check()
except FileExistsError:
    pass
 
# raise 를 사용한 예
if total < 0:
    raise Exception('Total Error')
```

## 14.3 파일 에러 처리 예제
아래 예제는 전형적인 파일 에러 처리를 보여주는 코드이다. 파일을 오픈할 때 에러가 발생하면, except IOError 블록을 실행한다. 파일오픈을 성공하면, try 블럭을 실행하고, finally 블럭에서 파일을 닫게 된다.

```python
try:
   fp = open("test.txt", "r")
   try:
      lines = fp.readlines()
      print(lines)
   finally:
      fp.close()
except IOError:
   print('파일에러')
```

참고로 다음은 with 문을 써서 해당 블럭이 끝나면 자동으로 파일을 닫는 코드의 예이다. Python의 with 문은 C#의 using 문과 비슷한 것으로 with 블럭이 끝날 때 자동으로 리소스를 해제하는 역활을 하는데, 특히 주목할 점은 with 블럭 내에서 어떤 Exception이 발생하더라도 반드시 리소스를 해제한다는 점이다.

```python
with open('test.txt', 'r') as fp:
    lines = fp.readlines()
    print(lines)
```
